Workbook

Sheet Sheet1
A1: 0 | B1: 46279 | C1: - | D1: - | E1: 0 | F1: =196 -> 196
A2: Day(1-15) | B2: Date | C2: Time | D2: Day(Monday - Friday) | E2: Vacant Table | F2: OccupiedTable | G2: Kamphaeng Saen Temperature Condition | H2: Rain and Flood Condition(Nakhon Pathom) | I2: Daily Maximum Temperature(Nakhon Pathom) | J2: Daily Rainfall (mm) (Nakhon Pathom) | L2: Note
A3: 1 | B3: 46280 | C3: 0.5 | D3: TuesDay | E3: 40 | F3: =196-Sheet1!$E3 -> 156 | G3: Not Hot | H3: No Flooding | I3: 33.5 | J3: 0.9 | L3: TotalTableจำนวนโต๊ะทั้งหมด = 196
A4: 1 | C4: 0.50347222 | D4: TuesDay | E4: 26 | F4: =196-Sheet1!$E4 -> 170 | G4: Not Hot | H4: No Flooding | I4: 33.5 | J4: 0.9
A5: 1 | C5: 0.50694444 | D5: TuesDay | E5: 13 | F5: =196-Sheet1!$E5 -> 183 | G5: Not Hot | H5: No Flooding | I5: 33.5 | J5: 0.9
A6: 1 | C6: 0.51041667 | D6: TuesDay | E6: 18 | F6: =196-Sheet1!$E6 -> 178 | G6: Not Hot | H6: No Flooding | I6: 33.5 | J6: 0.9
A7: 1 | C7: 0.51388889 | D7: TuesDay | E7: 28 | F7: =196-Sheet1!$E7 -> 168 | G7: Not Hot | H7: No Flooding | I7: 33.5 | J7: 0.9
A8: 1 | C8: 0.51736111 | D8: TuesDay | E8: 45 | F8: =196-Sheet1!$E8 -> 151 | G8: Not Hot | H8: No Flooding | I8: 33.5 | J8: 0.9
A9: 1 | C9: 0.52083333 | D9: TuesDay | E9: 61 | F9: =196-Sheet1!$E9 -> 135 | G9: Not Hot | H9: No Flooding | I9: 33.5 | J9: 0.9
A10: 1 | C10: 0.52430556 | D10: TuesDay | E10: 79 | F10: =196-Sheet1!$E10 -> 117 | G10: Not Hot | H10: No Flooding | I10: 33.5 | J10: 0.9
A11: 1 | C11: 0.52777778 | D11: TuesDay | E11: 99 | F11: =196-Sheet1!$E11 -> 97 | G11: Not Hot | H11: No Flooding | I11: 33.5 | J11: 0.9
A12: 1 | C12: 0.53125 | D12: TuesDay | E12: =129 -> 129 | F12: =196-Sheet1!$E12 -> 67 | G12: Not Hot | H12: No Flooding | I12: 33.5 | J12: 0.9
A13: 1 | C13: 0.53472222 | D13: TuesDay | E13: 150 | F13: =196-Sheet1!$E13 -> 46 | G13: Not Hot | H13: No Flooding | I13: 33.5 | J13: 0.9
A14: 1 | C14: 0.53819444 | D14: TuesDay | E14: 153 | F14: =196-Sheet1!$E14 -> 43 | G14: Not Hot | H14: No Flooding | I14: 33.5 | J14: 0.9
A15: 2 | B15: 46281 | C15: 0.5 | D15: Wednesday | E15: 30 | F15: =196-Sheet1!$E15 -> 166 | G15: Hot | H15: No Flooding | I15: 35.3 | J15: 9
A16: 2 | C16: 0.50347222 | D16: Wednesday | E16: 28 | F16: =196-Sheet1!$E16 -> 168 | G16: Hot | H16: No Flooding | I16: 35.3 | J16: 9
A17: 2 | C17: 0.50694444 | D17: Wednesday | E17: 11 | F17: =196-Sheet1!$E17 -> 185 | G17: Hot | H17: No Flooding | I17: 35.3 | J17: 9
A18: 2 | C18: 0.51041667 | D18: Wednesday | E18: 20 | F18: =196-Sheet1!$E18 -> 176 | G18: Hot | H18: No Flooding | I18: 35.3 | J18: 9
A19: 2 | C19: 0.51388889 | D19: Wednesday | E19: 15 | F19: =196-Sheet1!$E19 -> 181 | G19: Hot | H19: No Flooding | I19: 35.3 | J19: 9
A20: 2 | C20: 0.51736111 | D20: Wednesday | E20: 32 | F20: =196-Sheet1!$E20 -> 164 | G20: Hot | H20: No Flooding | I20: 35.3 | J20: 9
A21: 2 | C21: 0.52083333 | D21: Wednesday | E21: 43 | F21: =196-Sheet1!$E21 -> 153 | G21: Hot | H21: No Flooding | I21: 35.3 | J21: 9
A22: 2 | C22: 0.52430556 | D22: Wednesday | E22: 63 | F22: =196-Sheet1!$E22 -> 133 | G22: Hot | H22: No Flooding | I22: 35.3 | J22: 9
A23: 2 | C23: 0.52777778 | D23: Wednesday | E23: 83 | F23: =196-Sheet1!$E23 -> 113 | G23: Hot | H23: No Flooding | I23: 35.3 | J23: 9
A24: 2 | C24: 0.53125 | D24: Wednesday | E24: 122 | F24: =196-Sheet1!$E24 -> 74 | G24: Hot | H24: No Flooding | I24: 35.3 | J24: 9
A25: 2 | C25: 0.53472222 | D25: Wednesday | E25: 100 | F25: =196-Sheet1!$E25 -> 96 | G25: Hot | H25: No Flooding | I25: 35.3 | J25: 9
A26: 2 | C26: 0.53819444 | D26: Wednesday | E26: 149 | F26: =196-Sheet1!$E26 -> 47 | G26: Hot | H26: No Flooding | I26: 35.3 | J26: 9
A27: 3 | B27: 46282 | C27: 0.5 | D27: Thursday | E27: 45 | F27: =196-Sheet1!$E27 -> 151 | G27: Not Hot | H27: No Flooding | I27: 33.9 | J27: 7.9
A28: 3 | C28: 0.50347222 | D28: Thursday | E28: 38 | F28: =196-Sheet1!$E28 -> 158 | G28: Not Hot | H28: No Flooding | I28: 33.9 | J28: 7.9
A29: 3 | C29: 0.50694444 | D29: Thursday | E29: 2 | F29: =196-Sheet1!$E29 -> 194 | G29: Not Hot | H29: No Flooding | I29: 33.9 | J29: 7.9
A30: 3 | C30: 0.51041667 | D30: Thursday | E30: 2 | F30: =196-Sheet1!$E30 -> 194 | G30: Not Hot | H30: No Flooding | I30: 33.9 | J30: 7.9
A31: 3 | C31: 0.51388889 | D31: Thursday | E31: 18 | F31: =196-Sheet1!$E31 -> 178 | G31: Not Hot | H31: No Flooding | I31: 33.9 | J31: 7.9
A32: 3 | C32: 0.51736111 | D32: Thursday | E32: 21 | F32: =196-Sheet1!$E32 -> 175 | G32: Not Hot | H32: No Flooding | I32: 33.9 | J32: 7.9
A33: 3 | C33: 0.52083333 | D33: Thursday | E33: 55 | F33: =196-Sheet1!$E33 -> 141 | G33: Not Hot | H33: No Flooding | I33: 33.9 | J33: 7.9
A34: 3 | C34: 0.52430556 | D34: Thursday | E34: 67 | F34: =196-Sheet1!$E34 -> 129 | G34: Not Hot | H34: No Flooding | I34: 33.9 | J34: 7.9
A35: 3 | C35: 0.52777778 | D35: Thursday | E35: 87 | F35: =196-Sheet1!$E35 -> 109 | G35: Not Hot | H35: No Flooding | I35: 33.9 | J35: 7.9
A36: 3 | C36: 0.53125 | D36: Thursday | E36: 97 | F36: =196-Sheet1!$E36 -> 99 | G36: Not Hot | H36: No Flooding | I36: 33.9 | J36: 7.9
A37: 3 | C37: 0.53472222 | D37: Thursday | E37: 137 | F37: =196-Sheet1!$E37 -> 59 | G37: Not Hot | H37: No Flooding | I37: 33.9 | J37: 7.9
A38: 3 | C38: 0.53819444 | D38: Thursday | E38: 148 | F38: =196-Sheet1!$E38 -> 48 | G38: Not Hot | H38: No Flooding | I38: 33.9 | J38: 7.9
A39: 4 | B39: 46283 | C39: 0.5 | D39: Friday | E39: 102 | F39: =196-Sheet1!$E39 -> 94 | G39: Not Hot | H39: No Flooding | I39: 33.8 | J39: 0.4
A40: 4 | C40: 0.50347222 | D40: Friday | E40: 96 | F40: =196-Sheet1!$E40 -> 100 | G40: Not Hot | H40: No Flooding | I40: 33.8 | J40: 0.4
...
